Workbook

Sheet Executive Summary
A1: MPAJ SmartCross 2.2 Intersection Feasibility Study
A2: Initial feasibility model | Information verified 2026-09-07 | Not a construction or live-control approval
A4: Objective | B4: Compare the SmartCross 2.2 straight-road baseline with three-arm and four-arm concepts for potential MPAJ use.
A5: Scope | B5: Concept screening, mandatory safety gates, survey specification, infrastructure, governance, pilot and KPI framework.
A6: Evidence boundary | B6: Repository inspected. Interactive live-app visual inspection unavailable. No actual MPAJ candidate site or measured field dataset was supplied.
A7: Preliminary preference | B7: SC-T1-N ranks highest conceptually because it can isolate fewer movement conflicts than SC-X1, subject to site evidence and all safety gates.
A8: Decision rule | B8: No layout may be recommended for pilot while any critical safety gate is Fail, Not Assessed or Data Required.
A9: Critical gaps | B9: MPAJ-nominated sites; counts; speeds; geometry; crash/near-miss history; controller capability; accessibility; legal authority; RSA; supplier quotations.
A10: Next decision gate | B10: Complete baseline surveys and independent road-safety audit, identify road authority, then re-score the workbook with evidence.
A12: Configuration | B12: Concept score /5 | C12: Evidence completeness | D12: Risk-adjusted score /5 | E12: Mandatory-gate status | F12: Conditional recommendation
A13: SC-B0-N | B13: ='Weighted Decision Matrix'!B5 | C13: ='Weighted Decision Matrix'!C5 | D13: ='Weighted Decision Matrix'!D5 | E13: =IF(COUNTIF('Mandatory Safety Gates'!$D$4:$D$17,"Fail")>0,"FAIL",IF(COUNTIF('Mandatory Safety Gates'!$D$4:$D$17,"Data Required")+COUNTIF('Mandatory Safety Gates'!$D$4:$D$17,"Not Assessed")>0,"BLOCKED - DATA REQUIRED","CONDITIONAL")) | F13: ='Weighted Decision Matrix'!F5
A14: SC-B0-S | B14: ='Weighted Decision Matrix'!B6 | C14: ='Weighted Decision Matrix'!C6 | D14: ='Weighted Decision Matrix'!D6 | E14: =IF(COUNTIF('Mandatory Safety Gates'!$E$4:$E$17,"Fail")>0,"FAIL",IF(COUNTIF('Mandatory Safety Gates'!$E$4:$E$17,"Data Required")+COUNTIF('Mandatory Safety Gates'!$E$4:$E$17,"Not Assessed")>0,"BLOCKED - DATA REQUIRED","CONDITIONAL")) | F14: ='Weighted Decision Matrix'!F6
A15: SC-T1-N | B15: ='Weighted Decision Matrix'!B7 | C15: ='Weighted Decision Matrix'!C7 | D15: ='Weighted Decision Matrix'!D7 | E15: =IF(COUNTIF('Mandatory Safety Gates'!$F$4:$F$17,"Fail")>0,"FAIL",IF(COUNTIF('Mandatory Safety Gates'!$F$4:$F$17,"Data Required")+COUNTIF('Mandatory Safety Gates'!$F$4:$F$17,"Not Assessed")>0,"BLOCKED - DATA REQUIRED","CONDITIONAL")) | F15: ='Weighted Decision Matrix'!F7
A16: SC-T1-S | B16: ='Weighted Decision Matrix'!B8 | C16: ='Weighted Decision Matrix'!C8 | D16: ='Weighted Decision Matrix'!D8 | E16: =IF(COUNTIF('Mandatory Safety Gates'!$G$4:$G$17,"Fail")>0,"FAIL",IF(COUNTIF('Mandatory Safety Gates'!$G$4:$G$17,"Data Required")+COUNTIF('Mandatory Safety Gates'!$G$4:$G$17,"Not Assessed")>0,"BLOCKED - DATA REQUIRED","CONDITIONAL")) | F16: ='Weighted Decision Matrix'!F8
A17: SC-X1-N | B17: ='Weighted Decision Matrix'!B9 | C17: ='Weighted Decision Matrix'!C9 | D17: ='Weighted Decision Matrix'!D9 | E17: =IF(COUNTIF('Mandatory Safety Gates'!$H$4:$H$17,"Fail")>0,"FAIL",IF(COUNTIF('Mandatory Safety Gates'!$H$4:$H$17,"Data Required")+COUNTIF('Mandatory Safety Gates'!$H$4:$H$17,"Not Assessed")>0,"BLOCKED - DATA REQUIRED","CONDITIONAL")) | F17: ='Weighted Decision Matrix'!F9
A18: SC-X1-S | B18: ='Weighted Decision Matrix'!B10 | C18: ='Weighted Decision Matrix'!C10 | D18: ='Weighted Decision Matrix'!D10 | E18: =IF(COUNTIF('Mandatory Safety Gates'!$I$4:$I$17,"Fail")>0,"FAIL",IF(COUNTIF('Mandatory Safety Gates'!$I$4:$I$17,"Data Required")+COUNTIF('Mandatory Safety Gates'!$I$4:$I$17,"Not Assessed")>0,"BLOCKED - DATA REQUIRED","CONDITIONAL")) | F18: ='Weighted Decision Matrix'!F10

Sheet SmartCross Baseline Audit
A1: SmartCross 2.2 Baseline Audit
A2: Verification states reflect evidence actually available in this run.
A3: Feature | B3: Observed / repository finding | C3: Verification status | D3: Evidence location | E3: Limitation | F3: Adaptation implication | G3: Source ID
A4: Crossing geometry | B4: Straight two-way road with zebra crossing in component/source descriptions | C4: Verified in repository | D4: components/crossing-view.tsx; README.md | E4: Live visual not inspected | F4: Treat SC-B0 as simulator baseline, not surveyed geometry | G4: SRC-01
A5: Normal mode | B5: Normal zebra crossing; one no-violation plus 19 violation conditions = 20 conditions | C5: Verified in repository | D5: components/dashboard.tsx; lib/simulation.ts | E5: Counts derived from source; live menu not visually checked | F5: Reuse mode taxonomy | G5: SRC-01
A6: School mode | B6: School crossing; one no-violation plus 20 violations = 21 conditions | C6: Verified in repository | D6: components/dashboard.tsx; lib/simulation.ts | E6: Live rendering not visually checked | F6: Add junction-specific school refinements only | G6: SRC-01
A7: Protected WALK | B7: WALK released only when conflicting vehicles are STOP/route clear | C7: Verified in repository | D7: lib/motion.ts; README.md | E7: Physical controller not integrated | F7: Hard invariant for SC-T1/SC-X1 | G7: SRC-01
A8: Seven stages | B8: Approach, Initiation, Detected, Escalation, Conflict, Response, Outcome | C8: Verified in repository | D8: lib/types.ts | E8: Simulation sequence only | F8: Retain labels and map every adapted scenario | G8: SRC-01
A9: CCTV evidence | B9: Synthetic camera/plate evidence for simulated violations | C9: Verified in repository | D9: lib/types.ts; components/dashboard.tsx | E9: No live CCTV or evidential chain | F9: Legal and privacy gate before ANPR | G9: SRC-01
A10: Event log | B10: Local action-synchronised event records | C10: Verified in repository | D10: components/event-log.tsx; lib/simulation.ts | E10: Not an operational records system | F10: Specify retention, integrity and access controls | G10: SRC-01
A11: Incident escalation | B11: Human confirmation; local mock notifications; no external dispatch | C11: Verified in repository | D11: README.md; components/dashboard.tsx | E11: Not connected to emergency services | F11: Develop approved SOP and interfaces | G11: SRC-01
A12: PDF reporting | B12: Offline simulation report generation | C12: Verified in repository | D12: lib/pdf-report.ts; components/dashboard.tsx | E12: Not a statutory incident report | F12: Add evidence provenance and approval status | G12: SRC-01
A13: Diagnostic Inquiry | B13: Not established from inspected source set | C13: Not found | D13: Repository search | E13: Could exist in an uninspected deployment state | F13: Confirm with project owner | G13: SRC-01
A14: Accessibility | B14: Keyboard/skip-link semantics and wheelchair/elderly/child scenarios are represented | C14: Partially verified | D14: components/dashboard.tsx; lib/types.ts | E14: No field accessibility compliance can be inferred | F14: Require MS 1184 review and access audit | G14: SRC-01; SRC-06
... A18: Physical infrastructure | B18: No live traffic/CCTV/sensor/MPAJ connection | C18: Verified in repository | D18: README.md | E18: Simulation-only | F18: Every field module remains proposed | G18: SRC-01

Sheet Configuration Register
A1: Configuration Register
A2: IDs are the shared key used in both Excel and PDF.
A3: Variant ID | B3: Base ID | C3: Layout | D3: Mode | E3: Concept description | F3: Pedestrian-control concept | G3: Current decision | H3: Evidence state | I3: Drawing scale
A4: SC-B0-N | B4: SC-B0 | C4: Baseline | D4: Normal | E4: Existing straight-road SmartCross 2.2 simulator reference | F4: Existing protected WALK simulation sequence | G4: Simulation baseline only - not a field design | H4: Preliminary / data required | I4: Not to Scale
A5: SC-B0-S | B5: SC-B0 | C5: Baseline | D5: School | E5: Existing school-frontage simulator reference | F5: Existing protected WALK simulation sequence | G5: Simulation baseline only - not a field design | H5: Preliminary / data required | I5: Not to Scale
A6: SC-T1-N | B6: SC-T1 | C6: Three-arm T-junction | D6: Normal | E6: Major-road through movement plus one side-road approach | F6: Setback crossings; fully control conflicting turns during WALK | G6: Suitable subject to additional evidence | H6: Preliminary / data required | I6: Not to Scale
A7: SC-T1-S | B7: SC-T1 | C7: Three-arm T-junction | D7: School | E7: T-junction with school-period holding and parking controls | F7: Setback crossings; fully control conflicting turns during WALK | G7: Suitable subject to site modification | H7: Preliminary / data required | I7: Not to Scale
A8: SC-X1-N | B8: SC-X1 | C8: Four-arm crossroads | D8: Normal | E8: Crossroads with protected pedestrian phase options | F8: Fully protected pedestrian phase preferred for pilot screening | G8: Suitable only for specific MPAJ location types | H8: Preliminary / data required | I8: Not to Scale
A9: SC-X1-S | B9: SC-X1 | C9: Four-arm crossroads | D9: School | E9: Crossroads with school-period group detection and full protection | F9: Fully protected pedestrian phase preferred for pilot screening | G9: Suitable subject to additional evidence | H9: Preliminary / data required | I9: Not to Scale

Sheet Criteria and Weights
A1: Criteria and Weights
A2: Yellow cells are editable inputs. Weight total must equal 100%.
A3: Weight total | B3: =SUM(D6:D28) | D3: Control | E3: =IF(ABS(B3-1)<0.000001,"PASS","REVIEW WEIGHTS")
A5: Criterion ID | B5: Group | C5: Criterion | D5: Weight | E5: Required evidence | F5: Editable? | G5: Scoring definition
A6: C01 | B6: Demand | C6: Pedestrian demand | D6: 0.06 | E6: Counts by direction/user type and desire lines | F6: Yes | G6: 1 Very unsuitable | 2 Weak | 3 Conditional | 4 Suitable | 5 Highly suitable
A7: C02 | B7: Demand | C7: Vehicle demand | D7: 0.04 | E7: Approach and turning counts, classes and queues | F7: Yes | G7: 1 Very unsuitable | 2 Weak | 3 Conditional | 4 Suitable | 5 Highly suitable
A8: C03 | B8: Safety | C8: Operating speed | D8: 0.06 | E8: Posted, mean and 85th-percentile speed | F8: Yes | G8: 1 Very unsuitable | 2 Weak | 3 Conditional | 4 Suitable | 5 Highly suitable
A9: C04 | B9: Safety | C9: Safety history | D9: 0.07 | E9: Crashes, injuries, near misses and complaints | F9: Yes | G9: 1 Very unsuitable | 2 Weak | 3 Conditional | 4 Suitable | 5 Highly suitable
A10: C05 | B10: Safety | C10: Conflict complexity | D10: 0.07 | E10: Number, exposure and severity of movements | F10: Yes | G10: 1 Very unsuitable | 2 Weak | 3 Conditional | 4 Suitable | 5 Highly suitable
A11: C06 | B11: Geometry | C11: Geometry and visibility | D11: 0.06 | E11: Width, distance, grade, drainage and sight distance | F11: Yes | G11: 1 Very unsuitable | 2 Weak | 3 Conditional | 4 Suitable | 5 Highly suitable
A12: C07 | B12: Operations | C12: Signal operation | D12: 0.05 | E12: Controller, phases, intergreen and coordination | F12: Yes | G12: 1 Very unsuitable | 2 Weak | 3 Conditional | 4 Suitable | 5 Highly suitable
A13: C08 | B13: Inclusion | C13: Accessibility | D13: 0.06 | E13: Continuous accessible route and usable indications | F13: Yes | G13: 1 Very unsuitable | 2 Weak | 3 Conditional | 4 Suitable | 5 Highly suitable
A14: C09 | B14: Context | C14: School-zone suitability | D14: 0.04 | E14: Children, supervision, buses and parking | F14: Yes | G14: 1 Very unsuitable | 2 Weak | 3 Conditional | 4 Suitable | 5 Highly suitable
A15: C10 | B15: Context | C15: Public-transport access | D15: 0.03 | E15: LRT/bus demand and last-mile routes | F15: Yes | G15: 1 Very unsuitable | 2 Weak | 3 Conditional | 4 Suitable | 5 Highly suitable
A16: C11 | B16: Operations | C16: Emergency access | D16: 0.03 | E16: Priority operation and route continuity | F16: Yes | G16: 1 Very unsuitable | 2 Weak | 3 Conditional | 4 Suitable | 5 Highly suitable
A17: C12 | B17: Technology | C17: Infrastructure readiness | D17: 0.04 | E17: Power, comms, drainage, poles and cabinets | F17: Yes | G17: 1 Very unsuitable | 2 Weak | 3 Conditional | 4 Suitable | 5 Highly suitable
... A28: C23 | B28: Evidence | C28: Evidence quality | D28: 0.04 | E28: Completeness, recency and local applicability | F28: Yes | G28: 1 Very unsuitable | 2 Weak | 3 Conditional | 4 Suitable | 5 Highly suitable

Sheet Weighted Decision Matrix
A1: Weighted Decision Matrix
A2: Scores and confidence are editable screening inputs. Risk-adjusted score = weighted score x evidence completeness.
A4: Configuration | B4: Concept score /5 | C4: Evidence completeness | D4: Risk-adjusted /5 | E4: Rank | F4: Conditional recommendation
A5: SC-B0-N | B5: =SUMPRODUCT('Criteria and Weights'!$D$6:$D$28,G$13:G$35)/'Criteria and Weights'!$B$3 | C5: =G$10 | D5: =B5*C5 | E5: =RANK(D5,$D$5:$D$10,0) | F5: Simulation baseline only - not a field design
A6: SC-B0-S | B6: =SUMPRODUCT('Criteria and Weights'!$D$6:$D$28,H$13:H$35)/'Criteria and Weights'!$B$3 | C6: =H$10 | D6: =B6*C6 | E6: =RANK(D6,$D$5:$D$10,0) | F6: Simulation baseline only - not a field design
A7: SC-T1-N | B7: =SUMPRODUCT('Criteria and Weights'!$D$6:$D$28,I$13:I$35)/'Criteria and Weights'!$B$3 | C7: =I$10 | D7: =B7*C7 | E7: =RANK(D7,$D$5:$D$10,0) | F7: Suitable subject to additional evidence
A8: SC-T1-S | B8: =SUMPRODUCT('Criteria and Weights'!$D$6:$D$28,J$13:J$35)/'Criteria and Weights'!$B$3 | C8: =J$10 | D8: =B8*C8 | E8: =RANK(D8,$D$5:$D$10,0) | F8: Suitable subject to site modification
A9: SC-X1-N | B9: =SUMPRODUCT('Criteria and Weights'!$D$6:$D$28,K$13:K$35)/'Criteria and Weights'!$B$3 | C9: =K$10 | D9: =B9*C9 | E9: =RANK(D9,$D$5:$D$10,0) | F9: Suitable only for specific MPAJ location types
A10: SC-X1-S | B10: =SUMPRODUCT('Criteria and Weights'!$D$6:$D$28,L$13:L$35)/'Criteria and Weights'!$B$3 | C10: =L$10 | D10: =B10*C10 | E10: =RANK(D10,$D$5:$D$10,0) | F10: Evidence completeness inputs | G10: 0.75 | H10: 0.75 | I10: 0.4 | J10: 0.35 | K10: 0.35 | L10: 0.3
A12: Criterion ID | B12: Group | C12: Criterion | D12: Weight | E12: SC-B0-N | F12: SC-B0-S | G12: SC-T1-N | H12: SC-T1-S | I12: SC-X1-N | J12: SC-X1-S | K12: Rationale / data gap
A13: C01 | B13: Demand | C13: Pedestrian demand | D13: ='Criteria and Weights'!D6 | G13: 3 | H13: 3 | I13: 4 | J13: 5 | K13: 5 | L13: 5 | M13: DATA REQUIRED FROM MPAJ / SITE SURVEY: Counts by direction/user type and desire lines
A14: C02 | B14: Demand | C14: Vehicle demand | D14: ='Criteria and Weights'!D7 | G14: 3 | H14: 3 | I14: 4 | J14: 3 | K14: 4 | L14: 3 | M14: DATA REQUIRED FROM MPAJ / SITE SURVEY: Approach and turning counts, classes and queues
A15: C03 | B15: Safety | C15: Operating speed | D15: ='Criteria and Weights'!D8 | G15: 3 | H15: 3 | I15: 4 | J15: 4 | K15: 3 | L15: 3 | M15: DATA REQUIRED FROM MPAJ / SITE SURVEY: Posted, mean and 85th-percentile speed
A16: C04 | B16: Safety | C16: Safety history | D16: ='Criteria and Weights'!D9 | G16: 3 | H16: 3 | I16: 3 | J16: 3 | K16: 3 | L16: 3 | M16: DATA REQUIRED FROM MPAJ / SITE SURVEY: Crashes, injuries, near misses and complaints
A17: C05 | B17: Safety | C17: Conflict complexity | D17: ='Criteria and Weights'!D10 | G17: 4 | H17: 4 | I17: 4 | J17: 4 | K17: 2 | L17: 2 | M17: DATA REQUIRED FROM MPAJ / SITE SURVEY: Number, exposure and severity of movements
A18: C06 | B18: Geometry | C18: Geometry and visibility | D18: ='Criteria and Weights'!D11 | G18: 4 | H18: 4 | I18: 4 | J18: 4 | K18: 3 | L18: 3 | M18: DATA REQUIRED FROM MPAJ / SITE SURVEY: Width, distance, grade, drainage and sight distance
A19: C07 | B19: Operations | C19: Signal operation | D19: ='Criteria and Weights'!D12 | G19: 3 | H19: 3 | I19: 4 | J19: 4 | K19: 3 | L19: 3 | M19: DATA REQUIRED FROM MPAJ / SITE SURVEY: Controller, phases, intergreen and coordination
A20: C08 | B20: Inclusion | C20: Accessibility | D20: ='Criteria and Weights'!D13 | G20: 3 | H20: 4 | I20: 4 | J20: 5 | K20: 4 | L20: 5 | M20: DATA REQUIRED FROM MPAJ / SITE SURVEY: Continuous accessible route and usable indications
A21: C09 | B21: Context | C21: School-zone suitability | D21: ='Criteria and Weights'!D14 | G21: 2 | H21: 4 | I21: 3 | J21: 5 | K21: 3 | L21: 5 | M21: DATA REQUIRED FROM MPAJ / SITE SURVEY: Children, supervision, buses and parking
A22: C10 | B22: Context | C22: Public-transport access | D22: ='Criteria and Weights'!D15 | G22: 3 | H22: 2 | I22: 4 | J22: 3 | K22: 5 | L22: 4 | M22: DATA REQUIRED FROM MPAJ / SITE SURVEY: LRT/bus demand and last-mile routes
A23: C11 | B23: Operations | C23: Emergency access | D23: ='Criteria and Weights'!D16 | G23: 3 | H23: 3 | I23: 4 | J23: 4 | K23: 3 | L23: 3 | M23: DATA REQUIRED FROM MPAJ / SITE SURVEY: Priority operation and route continuity
A24: C12 | B24: Technology | C24: Infrastructure readiness | D24: ='Criteria and Weights'!D17 | G24: 3 | H24: 3 | I24: 4 | J24: 4 | K24: 3 | L24: 3 | M24: DATA REQUIRED FROM MPAJ / SITE SURVEY: Power, comms, drainage, poles and cabinets
... A35: C23 | B35: Evidence | C35: Evidence quality | D35: ='Criteria and Weights'!D28 | G35: 3 | H35: 3 | I35: 2 | J35: 2 | K35: 2 | L35: 2 | M35: DATA REQUIRED FROM MPAJ / SITE SURVEY: Completeness, recency and local applicability

Sheet Mandatory Safety Gates
A1: Mandatory Safety Gates
A2: Unresolved gates block pilot recommendation regardless of weighted score.
A3: Gate ID | B3: Mandatory gate | C3: Evidence required | D3: SC-B0-N | E3: SC-B0-S | F3: SC-T1-N | G3: SC-T1-S | H3: SC-X1-N | I3: SC-X1-S | J3: Owner | K3: Required action | L3: Source
A4: G01 | B4: Adequate sight distance | C4: Geometry / field survey | D4: Data Required | E4: Data Required | F4: Data Required | G4: Data Required | H4: Data Required | I4: Data Required | J4: MPAJ Engineering / relevant authority | K4: DATA REQUIRED FROM MPAJ / SITE SURVEY | L4: SRC-03; SRC-06; SRC-07; SRC-08
A5: G02 | B5: Safe pedestrian clearance time | C5: Counts, geometry and accessibility survey | D5: Data Required | E5: Data Required | F5: Data Required | G5: Data Required | H5: Data Required | I5: Data Required | J5: MPAJ Engineering / relevant authority | K5: DATA REQUIRED FROM MPAJ / SITE SURVEY | L5: SRC-03; SRC-06; SRC-07; SRC-08
A6: G03 | B6: No uncontrolled conflicting turn during WALK | C6: Controller design and stage tests | D6: Data Required | E6: Data Required | F6: Data Required | G6: Data Required | H6: Data Required | I6: Data Required | J6: MPAJ Engineering / relevant authority | K6: DATA REQUIRED FROM MPAJ / SITE SURVEY | L6: SRC-03; SRC-06; SRC-07; SRC-08
A7: G04 | B7: Continuous accessible crossing route | C7: Accessibility audit | D7: Data Required | E7: Data Required | F7: Data Required | G7: Data Required | H7: Data Required | I7: Data Required | J7: MPAJ Engineering / relevant authority | K7: DATA REQUIRED FROM MPAJ / SITE SURVEY | L7: SRC-03; SRC-06; SRC-07; SRC-08
A8: G05 | B8: Acceptable approach speed or approved treatment | C8: Speed study and design approval | D8: Data Required | E8: Data Required | F8: Data Required | G8: Data Required | H8: Data Required | I8: Data Required | J8: MPAJ Engineering / relevant authority | K8: DATA REQUIRED FROM MPAJ / SITE SURVEY | L8: SRC-03; SRC-06; SRC-07; SRC-08
A9: G06 | B9: Controller implements required interlocks | C9: Controller compatibility test | D9: Data Required | E9: Data Required | F9: Data Required | G9: Data Required | H9: Data Required | I9: Data Required | J9: MPAJ Engineering / relevant authority | K9: DATA REQUIRED FROM MPAJ / SITE SURVEY | L9: SRC-03; SRC-06; SRC-07; SRC-08
A10: G07 | B10: Queue spillback does not routinely block crossing | C10: Queue and capacity survey | D10: Data Required | E10: Data Required | F10: Data Required | G10: Data Required | H10: Data Required | I10: Data Required | J10: MPAJ Engineering / relevant authority | K10: DATA REQUIRED FROM MPAJ / SITE SURVEY | L10: SRC-03; SRC-06; SRC-07; SRC-08
A11: G08 | B11: Power/communications failure behaviour resolved | C11: Failure-mode test | D11: Data Required | E11: Data Required | F11: Data Required | G11: Data Required | H11: Data Required | I11: Data Required | J11: MPAJ Engineering / relevant authority | K11: DATA REQUIRED FROM MPAJ / SITE SURVEY | L11: SRC-03; SRC-06; SRC-07; SRC-08
A12: G09 | B12: Safe fixed-time or manual fallback | C12: Operations procedure and test | D12: Data Required | E12: Data Required | F12: Data Required | G12: Data Required | H12: Data Required | I12: Data Required | J12: MPAJ Engineering / relevant authority | K12: DATA REQUIRED FROM MPAJ / SITE SURVEY | L12: SRC-03; SRC-06; SRC-07; SRC-08
A13: G10 | B13: No critical controller cybersecurity exposure | C13: Independent security assessment | D13: Data Required | E13: Data Required | F13: Data Required | G13: Data Required | H13: Data Required | I13: Data Required | J13: MPAJ Engineering / relevant authority | K13: DATA REQUIRED FROM MPAJ / SITE SURVEY | L13: SRC-03; SRC-06; SRC-07; SRC-08
A14: G11 | B14: CCTV/ANPR processing lawfully approved | C14: Legal review and DPIA | D14: Data Required | E14: Data Required | F14: Data Required | G14: Data Required | H14: Data Required | I14: Data Required | J14: MPAJ Engineering / relevant authority | K14: DATA REQUIRED FROM MPAJ / SITE SURVEY | L14: SRC-03; SRC-06; SRC-07; SRC-08
... A17: G14 | B17: Emergency access conflict resolved | C17: Emergency-services consultation and test | D17: Data Required | E17: Data Required | F17: Data Required | G17: Data Required | H17: Data Required | I17: Data Required | J17: MPAJ Engineering / relevant authority | K17: DATA REQUIRED FROM MPAJ / SITE SURVEY | L17: SRC-03; SRC-06; SRC-07; SRC-08

Sheet Candidate Site Screening
A1: Candidate Site Screening
A2: No real site is nominated. Enter actual MPAJ locations only after jurisdiction and survey scope are confirmed.
A3: Candidate ID | B3: Actual MPAJ location | C3: Intersection type | D3: Nearby generators | E3: Ped peak | F3: Vehicle peak | G3: 85th % speed | H3: Crossing distance m | I3: Crash / near miss | J3: Lighting | K3: Accessibility | L3: Comms | M3: Readiness score | N3: Shortlist status | O3: Evidence status | P3: Notes
A4: SITE-T01 | C4: Three-arm T-junction | D4: DATA REQUIRED FROM MPAJ / SITE SURVEY | M4: =IF(COUNT(E4:L4)<4,"",AVERAGE(IFERROR(MIN(5,100/E4*5),""),IFERROR(MAX(1,5-G4/20),""))) | N4: Data Required | O4: Data Required | P4: MPAJ to nominate one candidate; map appearance alone is insufficient.
A5: SITE-X01 | C5: Four-arm crossroads | D5: DATA REQUIRED FROM MPAJ / SITE SURVEY | M5: =IF(COUNT(E5:L5)<4,"",AVERAGE(IFERROR(MIN(5,100/E5*5),""),IFERROR(MAX(1,5-G5/20),""))) | N5: Data Required | O5: Data Required | P5: MPAJ to nominate one candidate; confirm signal-controller and queue context.

Sheet Site Survey Requirements
A1: Site Survey Requirements
A2: Minimum evidence collection before a configuration can move beyond concept screening.
A3: Survey ID | B3: Survey item | C3: Method | D3: Unit | E3: Observation period | F3: Responsible party | G3: Quality check | H3: Completion status
A4: SV01 | B4: Pedestrian counts by direction/user category | C4: Video/manual classified counts | D4: pedestrians/15 min | E4: Weekday AM/PM peaks, school arrival/dismissal, off-peak, relevant weekend | F4: Traffic survey team | G4: Inter-observer check; privacy masks | H4: Not Started
A5: SV02 | B5: Vehicle approach and turning counts | C5: Classified junction count | D5: vehicles/15 min | E5: Same periods as pedestrian counts | F5: Traffic survey team | G5: Balance approaches/exits | H5: Not Started
A6: SV03 | B6: Vehicle speeds | C6: Calibrated radar; free-flow samples | D6: km/h | E6: Day/night and school active/inactive | F6: Traffic engineer | G6: Calibration certificate; sample sufficiency | H6: Not Started
A7: SV04 | B7: Queue length and delay | C7: Video trajectory/time study | D7: m, vehicles, seconds | E7: Peak and incident-prone periods | F7: Traffic engineer | G7: 95th-percentile and spillback locations | H7: Not Started
A8: SV05 | B8: Geometry and crossing distance | C8: Topographic/site survey | D8: m, %, degrees | E8: Daylight site visit | F8: Surveyor/engineer | G8: Independent dimension check | H8: Not Started
A9: SV06 | B9: Signal cycles and controller capability | C9: Controller records and field observation | D9: seconds / capability | E9: Multiple cycles each period | F9: Signal engineer | G9: Reconcile plan with observed states | H9: Not Started
A10: SV07 | B10: Crash/near-miss/complaint history | C10: Authority records and conflict study | D10: events/year; conflicts/hour | E10: At least recent multi-year record where available | F10: MPAJ/PDRM/MIROS | G10: Definitions and geocoding verified | H10: Not Started
A11: SV08 | B11: Visibility, lighting and blind spots | C11: Day/night inspection; lux and sight-distance checks | D11: lux, m | E11: Day, night, wet/adverse if feasible | F11: Road-safety auditor | G11: Photos, calibrated meter, all approaches | H11: Not Started
A12: SV09 | B12: Accessibility barriers | C12: Access audit with diverse users | D12: pass/fail; dimensions | E12: Day and operating peak | F12: Accessibility specialist | G12: Route continuity and user testing | H12: Not Started
A13: SV10 | B13: Drainage, utilities, installation space | C13: Services search and inspection | D13: location/capacity | E13: Daylight; wet-weather evidence | F13: Civil/electrical engineer | G13: Utility plans and potholing as approved | H13: Not Started
A14: SV11 | B14: CCTV and communications coverage | C14: RF/fibre survey and camera trial | D14: signal, latency, coverage | E14: Day/night/peak | F14: ICT/security team | G14: Packet loss, failover and privacy masking | H14: Not Started
A15: SV12 | B15: Stakeholder feedback | C15: Structured engagement | D15: themes / support | E15: Before design and after trial | F15: MPAJ community team | G15: Record vulnerable-user representation | H15: Not Started

Sheet Vehicle Movement Matrix
A1: Vehicle Movement Matrix
A2: Conceptual movement controls; validate against site geometry and controller phasing.
A3: Configuration | B3: Approach | C3: Movement | D3: Conflicting pedestrian route | E3: Proposed phase | F3: Control | G3: Failure response | H3: Evidence state
A4: SC-B0 | B4: East | C4: Through | D4: Adjacent/crossed pedestrian leg - site mapping required | E4: Vehicle phase with pedestrian WAIT | F4: Stop and prove stationary before conflicting WALK | G4: All-red/WAIT; manual safe plan | H4: Conceptual
A5: SC-B0 | B5: West | C5: Through | D5: Adjacent/crossed pedestrian leg - site mapping required | E5: Vehicle phase with pedestrian WAIT | F5: Stop and prove stationary before conflicting WALK | G5: All-red/WAIT; manual safe plan | H5: Conceptual
A6: SC-T1 | B6: East | C6: Left | D6: Adjacent/crossed pedestrian leg - site mapping required | E6: Vehicle phase with pedestrian WAIT | F6: Stop and prove stationary before conflicting WALK | G6: All-red/WAIT; manual safe plan | H6: Conceptual
A7: SC-T1 | B7: East | C7: Through | D7: Adjacent/crossed pedestrian leg - site mapping required | E7: Vehicle phase with pedestrian WAIT | F7: Stop and prove stationary before conflicting WALK | G7: All-red/WAIT; manual safe plan | H7: Conceptual
A8: SC-T1 | B8: East | C8: Right | D8: Adjacent/crossed pedestrian leg - site mapping required | E8: Vehicle phase with pedestrian WAIT | F8: Stop and prove stationary before conflicting WALK | G8: All-red/WAIT; manual safe plan | H8: Conceptual
A9: SC-T1 | B9: West | C9: Left | D9: Adjacent/crossed pedestrian leg - site mapping required | E9: Vehicle phase with pedestrian WAIT | F9: Stop and prove stationary before conflicting WALK | G9: All-red/WAIT; manual safe plan | H9: Conceptual
A10: SC-T1 | B10: West | C10: Through | D10: Adjacent/crossed pedestrian leg - site mapping required | E10: Vehicle phase with pedestrian WAIT | F10: Stop and prove stationary before conflicting WALK | G10: All-red/WAIT; manual safe plan | H10: Conceptual
A11: SC-T1 | B11: West | C11: Right | D11: Adjacent/crossed pedestrian leg - site mapping required | E11: Vehicle phase with pedestrian WAIT | F11: Stop and prove stationary before conflicting WALK | G11: All-red/WAIT; manual safe plan | H11: Conceptual
A12: SC-T1 | B12: South | C12: Left | D12: Adjacent/crossed pedestrian leg - site mapping required | E12: Vehicle phase with pedestrian WAIT | F12: Stop and prove stationary before conflicting WALK | G12: All-red/WAIT; manual safe plan | H12: Conceptual
A13: SC-T1 | B13: South | C13: Right | D13: Adjacent/crossed pedestrian leg - site mapping required | E13: Vehicle phase with pedestrian WAIT | F13: Stop and prove stationary before conflicting WALK | G13: All-red/WAIT; manual safe plan | H13: Conceptual
A14: SC-X1 | B14: North | C14: Left | D14: Adjacent/crossed pedestrian leg - site mapping required | E14: Vehicle phase with pedestrian WAIT | F14: Stop and prove stationary before conflicting WALK | G14: All-red/WAIT; manual safe plan | H14: Conceptual
... A25: SC-X1 | B25: West | C25: Right | D25: Adjacent/crossed pedestrian leg - site mapping required | E25: Vehicle phase with pedestrian WAIT | F25: Stop and prove stationary before conflicting WALK | G25: All-red/WAIT; manual safe plan | H25: Conceptual

Sheet Pedestrian Route Matrix
A1: Pedestrian Route Matrix
A2: Distances and exact conflict counts remain blank until a candidate site is surveyed.
A3: Configuration | B3: Route ID | C3: Origin | D3: Destination | E3: Crossing leg | F3: Distance m | G3: Accessible route | H3: Conflict count | I3: Evidence state
A4: SC-B0 | B4: SC-B0-P1 | C4: Kerb 1A | D4: Kerb 1B | E4: Main road | G4: DATA REQUIRED FROM MPAJ / SITE SURVEY | I4: Data Required
A5: SC-T1 | B5: SC-T1-P1 | C5: Kerb 1A | D5: Kerb 1B | E5: West major | G5: DATA REQUIRED FROM MPAJ / SITE SURVEY | I5: Data Required
A6: SC-T1 | B6: SC-T1-P2 | C6: Kerb 2A | D6: Kerb 2B | E6: East major | G6: DATA REQUIRED FROM MPAJ / SITE SURVEY | I6: Data Required
A7: SC-T1 | B7: SC-T1-P3 | C7: Kerb 3A | D7: Kerb 3B | E7: Side road | G7: DATA REQUIRED FROM MPAJ / SITE SURVEY | I7: Data Required
A8: SC-X1 | B8: SC-X1-P1 | C8: Kerb 1A | D8: Kerb 1B | E8: North | G8: DATA REQUIRED FROM MPAJ / SITE SURVEY | I8: Data Required
A9: SC-X1 | B9: SC-X1-P2 | C9: Kerb 2A | D9: Kerb 2B | E9: East | G9: DATA REQUIRED FROM MPAJ / SITE SURVEY | I9: Data Required
A10: SC-X1 | B10: SC-X1-P3 | C10: Kerb 3A | D10: Kerb 3B | E10: South | G10: DATA REQUIRED FROM MPAJ / SITE SURVEY | I10: Data Required
A11: SC-X1 | B11: SC-X1-P4 | C11: Kerb 4A | D11: Kerb 4B | E11: West | G11: DATA REQUIRED FROM MPAJ / SITE SURVEY | I11: Data Required

Sheet Scenario Register
A1: Scenario Register
A2: Each scenario is mapped for SC-B0, SC-T1 and SC-X1; adaptations retain the protected-WALK invariant.
A3: Scenario key | B3: Scenario ID | C3: Type | D3: Scenario | E3: Configuration | F3: Initial positions | G3: Trigger | H3: Pedestrian movement | I3: Vehicle movement | J3: Signal state | K3: Detection | L3: Conflict point | M3: System response | N3: Safe outcome | O3: Validation test
A4: SC-B0-S01 | B4: S01 | C4: Normal | D4: Protected pedestrian request | E4: SC-B0 | F4: DATA REQUIRED FROM MPAJ / SITE SURVEY | G4: Protected pedestrian request | H4: WAIT/HOLD until all relevant conflicting movements are proven stopped; extend for slow users | I4: Layout-specific approach/turning path; exact coordinates require simulation geometry | J4: Vehicle RED before WALK; WAIT on uncertainty/failure | K4: Sensor fusion with confidence threshold | L4: SC-B0 conflict zone - survey/simulation required | M4: Baseline sequence retained | N4: Pedestrian protected or held; event logged; human review for violation/emergency | O4: Assert no WALK with any conflicting movement permissive; verify seven stages and final zero speed
A5: SC-B0-S02 | B5: S02 | C5: Violation | D5: Left-turn conflict | E5: SC-B0 | F5: DATA REQUIRED FROM MPAJ / SITE SURVEY | G5: Left-turn conflict | H5: WAIT/HOLD until all relevant conflicting movements are proven stopped; extend for slow users | I5: Layout-specific approach/turning path; exact coordinates require simulation geometry | J5: Vehicle RED before WALK; WAIT on uncertainty/failure | K5: Sensor fusion with confidence threshold | L5: SC-B0 conflict zone - survey/simulation required | M5: Baseline sequence retained | N5: Pedestrian protected or held; event logged; human review for violation/emergency | O5: Assert no WALK with any conflicting movement permissive; verify seven stages and final zero speed
A6: SC-B0-S03 | B6: S03 | C6: Violation | D6: Right-turn conflict | E6: SC-B0 | F6: DATA REQUIRED FROM MPAJ / SITE SURVEY | G6: Right-turn conflict | H6: WAIT/HOLD until all relevant conflicting movements are proven stopped; extend for slow users | I6: Layout-specific approach/turning path; exact coordinates require simulation geometry | J6: Vehicle RED before WALK; WAIT on uncertainty/failure | K6: Sensor fusion with confidence threshold | L6: SC-B0 conflict zone - survey/simulation required | M6: Baseline sequence retained | N6: Pedestrian protected or held; event logged; human review for violation/emergency | O6: Assert no WALK with any conflicting movement permissive; verify seven stages and final zero speed
A7: SC-B0-S04 | B7: S04 | C7: Violation | D7: Through-vehicle conflict | E7: SC-B0 | F7: DATA REQUIRED FROM MPAJ / SITE SURVEY | G7: Through-vehicle conflict | H7: WAIT/HOLD until all relevant conflicting movements are proven stopped; extend for slow users | I7: Layout-specific approach/turning path; exact coordinates require simulation geometry | J7: Vehicle RED before WALK; WAIT on uncertainty/failure | K7: Sensor fusion with confidence threshold | L7: SC-B0 conflict zone - survey/simulation required | M7: Baseline sequence retained | N7: Pedestrian protected or held; event logged; human review for violation/emergency | O7: Assert no WALK with any conflicting movement permissive; verify seven stages and final zero speed
A8: SC-B0-S05 | B8: S05 | C8: Violation | D8: Red-light violation | E8: SC-B0 | F8: DATA REQUIRED FROM MPAJ / SITE SURVEY | G8: Red-light violation | H8: WAIT/HOLD until all relevant conflicting movements are proven stopped; extend for slow users | I8: Layout-specific approach/turning path; exact coordinates require simulation geometry | J8: Vehicle RED before WALK; WAIT on uncertainty/failure | K8: Sensor fusion with confidence threshold | L8: SC-B0 conflict zone - survey/simulation required | M8: Baseline sequence retained | N8: Pedestrian protected or held; event logged; human review for violation/emergency | O8: Assert no WALK with any conflicting movement permissive; verify seven stages and final zero speed
A9: SC-B0-S06 | B9: S06 | C9: Violation | D9: Speeding approach | E9: SC-B0 | F9: DATA REQUIRED FROM MPAJ / SITE SURVEY | G9: Speeding approach | H9: WAIT/HOLD until all relevant conflicting movements are proven stopped; extend for slow users | I9: Layout-specific approach/turning path; exact coordinates require simulation geometry | J9: Vehicle RED before WALK; WAIT on uncertainty/failure | K9: Sensor fusion with confidence threshold | L9: SC-B0 conflict zone - survey/simulation required | M9: Baseline sequence retained | N9: Pedestrian protected or held; event logged; human review for violation/emergency | O9: Assert no WALK with any conflicting movement permissive; verify seven stages and final zero speed
A10: SC-B0-S07 | B10: S07 | C10: Violation | D10: Failure to yield | E10: SC-B0 | F10: DATA REQUIRED FROM MPAJ / SITE SURVEY | G10: Failure to yield | H10: WAIT/HOLD until all relevant conflicting movements are proven stopped; extend for slow users | I10: Layout-specific approach/turning path; exact coordinates require simulation geometry | J10: Vehicle RED before WALK; WAIT on uncertainty/failure | K10: Sensor fusion with confidence threshold | L10: SC-B0 conflict zone - survey/simulation required | M10: Baseline sequence retained | N10: Pedestrian protected or held; event logged; human review for violation/emergency | O10: Assert no WALK with any conflicting movement permissive; verify seven stages and final zero speed
A11: SC-B0-S08 | B11: S08 | C11: Violation | D11: Vehicle stopping over crossing | E11: SC-B0 | F11: DATA REQUIRED FROM MPAJ / SITE SURVEY | G11: Vehicle stopping over crossing | H11: WAIT/HOLD until all relevant conflicting movements are proven stopped; extend for slow users | I11: Layout-specific approach/turning path; exact coordinates require simulation geometry | J11: Vehicle RED before WALK; WAIT on uncertainty/failure | K11: Sensor fusion with confidence threshold | L11: SC-B0 conflict zone - survey/simulation required | M11: Baseline sequence retained | N11: Pedestrian protected or held; event logged; human review for violation/emergency | O11: Assert no WALK with any conflicting movement permissive; verify seven stages and final zero speed
A12: SC-B0-S09 | B12: S09 | C12: Violation | D12: Queue spillback | E12: SC-B0 | F12: DATA REQUIRED FROM MPAJ / SITE SURVEY | G12: Queue spillback | H12: WAIT/HOLD until all relevant conflicting movements are proven stopped; extend for slow users | I12: Layout-specific approach/turning path; exact coordinates require simulation geometry | J12: Vehicle RED before WALK; WAIT on uncertainty/failure | K12: Sensor fusion with confidence threshold | L12: SC-B0 conflict zone - survey/simulation required | M12: Baseline sequence retained | N12: Pedestrian protected or held; event logged; human review for violation/emergency | O12: Assert no WALK with any conflicting movement permissive; verify seven stages and final zero speed
A13: SC-B0-S10 | B13: S10 | C13: Violation | D13: Illegal U-turn | E13: SC-B0 | F13: DATA REQUIRED FROM MPAJ / SITE SURVEY | G13: Illegal U-turn | H13: WAIT/HOLD until all relevant conflicting movements are proven stopped; extend for slow users | I13: Layout-specific approach/turning path; exact coordinates require simulation geometry | J13: Vehicle RED before WALK; WAIT on uncertainty/failure | K13: Sensor fusion with confidence threshold | L13: SC-B0 conflict zone - survey/simulation required | M13: Baseline sequence retained | N13: Pedestrian protected or held; event logged; human review for violation/emergency | O13: Assert no WALK with any conflicting movement permissive; verify seven stages and final zero speed
A14: SC-B0-S11 | B14: S11 | C14: Violation | D14: Motorcycle filtering | E14: SC-B0 | F14: DATA REQUIRED FROM MPAJ / SITE SURVEY | G14: Motorcycle filtering | H14: WAIT/HOLD until all relevant conflicting movements are proven stopped; extend for slow users | I14: Layout-specific approach/turning path; exact coordinates require simulation geometry | J14: Vehicle RED before WALK; WAIT on uncertainty/failure | K14: Sensor fusion with confidence threshold | L14: SC-B0 conflict zone - survey/simulation required | M14: Baseline sequence retained | N14: Pedestrian protected or held; event logged; human review for violation/emergency | O14: Assert no WALK with any conflicting movement permissive; verify seven stages and final zero speed
... A75: SC-X1-S24 | B75: S24 | C75: Emergency | D75: Emergency-vehicle approach | E75: SC-X1 | F75: DATA REQUIRED FROM MPAJ / SITE SURVEY | G75: Emergency-vehicle approach | H75: WAIT/HOLD until all relevant conflicting movements are proven stopped; extend for slow users | I75: Layout-specific approach/turning path; exact coordinates require simulation geometry | J75: Vehicle RED before WALK; WAIT on uncertainty/failure | K75: Sensor fusion with confidence threshold | L75: SC-X1 conflict zone - survey/simulation required | M75: Adapt detection and conflict mapping to SC-X1 legs; no change to STOP-before-WALK | N75: Pedestrian protected or held; event logged; human review for violation/emergency | O75: Assert no WALK with any conflicting movement permissive; verify seven stages and final zero speed

Sheet Seven-Stage Timeline Mapping
A1: Seven-Stage Timeline Mapping
A2: Traceable adaptation of every scenario to the existing seven-stage vocabulary.
A3: Scenario key | B3: Configuration | C3: Scenario | D3: Approach | E3: Initiation | F3: Detected | G3: Escalation | H3: Conflict | I3: Response | J3: Outcome | K3: Adaptation note
A4: SC-B0-S01 | B4: SC-B0 | C4: Protected pedestrian request | D4: Actors enter monitored approaches | E4: Demand or abnormal movement begins | F4: Protected pedestrian request indication is correlated | G4: Risk state raised; WALK remains gated | H4: Layout-specific path convergence is evaluated | I4: STOP/HOLD or protected WALK after clearance | J4: Safe state and auditable record | K4: SC-B0 vocabulary preserved; junction legs added for T1/X1
A5: SC-B0-S02 | B5: SC-B0 | C5: Left-turn conflict | D5: Actors enter monitored approaches | E5: Demand or abnormal movement begins | F5: Left-turn conflict indication is correlated | G5: Risk state raised; WALK remains gated | H5: Layout-specific path convergence is evaluated | I5: STOP/HOLD or protected WALK after clearance | J5: Safe state and auditable record | K5: SC-B0 vocabulary preserved; junction legs added for T1/X1
A6: SC-B0-S03 | B6: SC-B0 | C6: Right-turn conflict | D6: Actors enter monitored approaches | E6: Demand or abnormal movement begins | F6: Right-turn conflict indication is correlated | G6: Risk state raised; WALK remains gated | H6: Layout-specific path convergence is evaluated | I6: STOP/HOLD or protected WALK after clearance | J6: Safe state and auditable record | K6: SC-B0 vocabulary preserved; junction legs added for T1/X1
A7: SC-B0-S04 | B7: SC-B0 | C7: Through-vehicle conflict | D7: Actors enter monitored approaches | E7: Demand or abnormal movement begins | F7: Through-vehicle conflict indication is correlated | G7: Risk state raised; WALK remains gated | H7: Layout-specific path convergence is evaluated | I7: STOP/HOLD or protected WALK after clearance | J7: Safe state and auditable record | K7: SC-B0 vocabulary preserved; junction legs added for T1/X1
A8: SC-B0-S05 | B8: SC-B0 | C8: Red-light violation | D8: Actors enter monitored approaches | E8: Demand or abnormal movement begins | F8: Red-light violation indication is correlated | G8: Risk state raised; WALK remains gated | H8: Layout-specific path convergence is evaluated | I8: STOP/HOLD or protected WALK after clearance | J8: Safe state and auditable record | K8: SC-B0 vocabulary preserved; junction legs added for T1/X1
A9: SC-B0-S06 | B9: SC-B0 | C9: Speeding approach | D9: Actors enter monitored approaches | E9: Demand or abnormal movement begins | F9: Speeding approach indication is correlated | G9: Risk state raised; WALK remains gated | H9: Layout-specific path convergence is evaluated | I9: STOP/HOLD or protected WALK after clearance | J9: Safe state and auditable record | K9: SC-B0 vocabulary preserved; junction legs added for T1/X1
A10: SC-B0-S07 | B10: SC-B0 | C10: Failure to yield | D10: Actors enter monitored approaches | E10: Demand or abnormal movement begins | F10: Failure to yield indication is correlated | G10: Risk state raised; WALK remains gated | H10: Layout-specific path convergence is evaluated | I10: STOP/HOLD or protected WALK after clearance | J10: Safe state and auditable record | K10: SC-B0 vocabulary preserved; junction legs added for T1/X1
A11: SC-B0-S08 | B11: SC-B0 | C11: Vehicle stopping over crossing | D11: Actors enter monitored approaches | E11: Demand or abnormal movement begins | F11: Vehicle stopping over crossing indication is correlated | G11: Risk state raised; WALK remains gated | H11: Layout-specific path convergence is evaluated | I11: STOP/HOLD or protected WALK after clearance | J11: Safe state and auditable record | K11: SC-B0 vocabulary preserved; junction legs added for T1/X1
A12: SC-B0-S09 | B12: SC-B0 | C12: Queue spillback | D12: Actors enter monitored approaches | E12: Demand or abnormal movement begins | F12: Queue spillback indication is correlated | G12: Risk state raised; WALK remains gated | H12: Layout-specific path convergence is evaluated | I12: STOP/HOLD or protected WALK after clearance | J12: Safe state and auditable record | K12: SC-B0 vocabulary preserved; junction legs added for T1/X1
A13: SC-B0-S10 | B13: SC-B0 | C13: Illegal U-turn | D13: Actors enter monitored approaches | E13: Demand or abnormal movement begins | F13: Illegal U-turn indication is correlated | G13: Risk state raised; WALK remains gated | H13: Layout-specific path convergence is evaluated | I13: STOP/HOLD or protected WALK after clearance | J13: Safe state and auditable record | K13: SC-B0 vocabulary preserved; junction legs added for T1/X1
A14: SC-B0-S11 | B14: SC-B0 | C14: Motorcycle filtering | D14: Actors enter monitored approaches | E14: Demand or abnormal movement begins | F14: Motorcycle filtering indication is correlated | G14: Risk state raised; WALK remains gated | H14: Layout-specific path convergence is evaluated | I14: STOP/HOLD or protected WALK after clearance | J14: Safe state and auditable record | K14: SC-B0 vocabulary preserved; junction legs added for T1/X1
... A75: SC-X1-S24 | B75: SC-X1 | C75: Emergency-vehicle approach | D75: Actors enter monitored approaches | E75: Demand or abnormal movement begins | F75: Emergency-vehicle approach indication is correlated | G75: Risk state raised; WALK remains gated | H75: Layout-specific path convergence is evaluated | I75: STOP/HOLD or protected WALK after clearance | J75: Safe state and auditable record | K75: SC-B0 vocabulary preserved; junction legs added for T1/X1

Sheet Conflict and Risk Register
A1: Conflict and Risk Register
A2: Likelihood and severity are preliminary inputs. Residual risk requires validation after mitigation.
A3: Risk ID | B3: Configuration | C3: Hazard | D3: Condition | E3: Likelihood 1-5 | F3: Severity 1-5 | G3: Inherent risk | H3: Mitigation | I3: Residual likelihood | J3: Residual severity | K3: Residual risk | L3: Owner | N3: Risk band | O3: Count
A4: R01 | B4: SC-T1 | C4: Turning vehicle conflicts with crossing | D4: Normal/peak | E4: 4 | F4: 5 | G4: =E4*F4 | H4: Separate phase; setback crossing; detection; stop proof | I4: 2 | J4: 5 | K4: =I4*J4 | L4: MPAJ / design team | N4: Critical (15-25) | O4: =COUNTIF(G4:G15,">=15")
A5: R02 | B5: SC-T1 | C5: Side-road queue blocks crossing | D5: Peak/school | E5: 3 | F5: 4 | G5: =E5*F5 | H5: Queue detection; keep-clear; parking management | I5: 2 | J5: 4 | K5: =I5*J5 | L5: MPAJ / design team | N5: High (8-14) | O5: =COUNTIFS(G4:G15,">=8",G4:G15,"<15")
A6: R03 | B6: SC-T1 | C6: Sightline obscured by parking | D6: School/night | E6: 4 | F6: 5 | G6: =E6*F6 | H6: Keep-clear zone; relocation; lighting; enforcement | I6: 2 | J6: 5 | K6: =I6*J6 | L6: MPAJ / design team | N6: Moderate (1-7) | O6: =COUNTIFS(G4:G15,">=1",G4:G15,"<8")
A7: R04 | B7: SC-X1 | C7: Multiple turn conflicts during WALK | D7: All periods | E7: 5 | F7: 5 | G7: =E7*F7 | H7: Fully protected pedestrian phase; prohibit permissive turns | I7: 2 | J7: 5 | K7: =I7*J7 | L7: MPAJ / design team
A8: R05 | B8: SC-X1 | C8: Queue spillback across multiple legs | D8: Peak | E8: 4 | F8: 4 | G8: =E8*F8 | H8: Capacity study; queue detection; coordination | I8: 2 | J8: 4 | K8: =I8*J8 | L8: MPAJ / design team
A9: R06 | B9: SC-X1 | C9: Pedestrian delay causes non-compliance | D9: Peak | E9: 4 | F9: 4 | G9: =E9*F9 | H9: Demand-responsive timing within safe limits | I9: 2 | J9: 4 | K9: =I9*J9 | L9: MPAJ / design team
A10: R07 | B10: All | C10: Slow pedestrian not clear at phase end | D10: All periods | E10: 3 | F10: 5 | G10: =E10*F10 | H10: Presence extension; conservative clearance; refuge if justified | I10: 1 | J10: 5 | K10: =I10*J10 | L10: MPAJ / design team
A11: R08 | B11: All | C11: Sensor false negative | D11: Night/weather/occlusion | E11: 3 | F11: 5 | G11: =E11*F11 | H11: Redundancy; conservative fail-safe; performance test | I11: 1 | J11: 5 | K11: =I11*J11 | L11: MPAJ / design team
A12: R09 | B12: All | C12: Controller/network compromise | D12: Degraded/cyber | E12: 3 | F12: 5 | G12: =E12*F12 | H12: Safety isolation; segmentation; signed config; RBAC | I12: 1 | J12: 5 | K12: =I12*J12 | L12: MPAJ / design team
A13: R10 | B13: All | C13: Unlawful ANPR processing | D13: Operations | E13: 3 | F13: 4 | G13: =E13*F13 | H13: Disable until legal authority/DPIA/retention approved | I13: 1 | J13: 4 | K13: =I13*J13 | L13: MPAJ / design team
A14: R11 | B14: All | C14: Power or communications failure | D14: Failure | E14: 3 | F14: 5 | G14: =E14*F14 | H14: UPS; local fixed safe plan; health alarm; manual control | I14: 1 | J14: 5 | K14: =I14*J14 | L14: MPAJ / design team
A15: R12 | B15: All | C15: Emergency route obstructed | D15: Emergency | E15: 2 | F15: 5 | G15: =E15*F15 | H15: Agency consultation; priority plan; fail-safe test | I15: 1 | J15: 5 | K15: =I15*J15 | L15: MPAJ / design team

Sheet Infrastructure Schedule
A1: Infrastructure Schedule
A2: Quantities and exact locations remain design inputs; unnecessary technology is excluded.
A3: Module ID | B3: Module | C3: Function | D3: SC-B0 status | E3: SC-T1 requirement | F3: SC-X1 requirement | G3: Proposed location | H3: Quantity | I3: Power | J3: Communications | K3: Data produced | L3: Dependency | M3: Privacy | N3: Cybersecurity control | O3: Maintenance | P3: Safe fallback | Q3: Cost category | R3: Evidence / assumption
A4: M01 | B4: Traffic-signal controller | C4: Enforces safety interlocks | D4: Conceptual simulation logic | E4: Required | F4: Required | G4: Controller cabinet | I4: Mains + UPS | J4: Secure field network | K4: State/event telemetry | L4: Independent safety boundary | M4: No personal data | N4: Network segmentation; signed configuration | O4: Periodic inspection and firmware governance | P4: Fixed-time/manual safe plan | Q4: High | R4: Proposed requirement; verify with site design
A5: M02 | B5: Vehicle signal heads | C5: Controls each conflicting movement | D5: Simulated indications | E5: Required | F5: Required | G5: Each controlled approach | I5: Mains | J5: Controller copper/fibre | K5: Aspect state | L5: M01 | M5: None | N5: Cabinet access control | O5: Lamp/LED inspection | P5: All-red / authority procedure | Q5: High | R5: Proposed requirement; verify with site design
A6: M03 | B6: Pedestrian signal heads | C6: WALK/WAIT indication | D6: Simulated indications | E6: Required | F6: Required | G6: Each crossing end | I6: Mains | J6: Controller link | K6: Aspect state | L6: M01 | M6: None | N6: Tamper-resistant installation | O6: Visibility and alignment checks | P6: WAIT on fault | Q6: Medium | R6: Proposed requirement; verify with site design
A7: M04 | B7: Accessible push button | C7: Accessible demand call | D7: Not established in live app | E7: Required | F7: Required | G7: Reachable waiting zone | I7: Low voltage | J7: Controller input | K7: Request event | L7: M01 | M7: Minimal | N7: Debounce; protected input | O7: Cleaning and functional test | P7: Fixed-time call or manual assist | Q7: Low | R7: Proposed requirement; verify with site design
A8: M05 | B8: Touchless request sensor | C8: Optional hygienic call | D8: Not verified | E8: Optional | F8: Optional | G8: Waiting zone | I8: Low voltage | J8: Controller input | K8: Presence/request | L8: M01 | M8: Avoid biometric capture | N8: Rate limiting; health checks | O8: Calibration | P8: Push button remains available | Q8: Low | R8: Proposed requirement; verify with site design
A9: M06 | B9: Countdown display | C9: Communicates remaining crossing time | D9: Repository shows countdown | E9: Recommended | F9: Recommended | G9: Pedestrian signal pole | I9: Low voltage | J9: Controller | K9: Time remaining | L9: M01 | M9: None | N9: Read-only field interface | O9: Display inspection | P9: WALK/WAIT heads remain authoritative | Q9: Low | R9: Proposed requirement; verify with site design
A10: M07 | B10: Audible/tactile indicator | C10: Supports sensory accessibility | D10: Not verified | E10: Required subject to audit | F10: Required subject to audit | G10: Push-button pole | I10: Low voltage | J10: Controller | K10: Status only | L10: M01 | M10: None | N10: Configuration control | O10: Volume/tactile testing | P10: WAIT/fault indication | Q10: Medium | R10: Proposed requirement; verify with site design
A11: M08 | B11: AI CCTV camera | C11: Detects trajectories and events | D11: Simulated CCTV evidence | E11: Conditional | F11: Conditional | G11: Approach/overhead with privacy mask | I11: PoE/UPS | J11: Secure IP network | K11: Anonymous track; event clip if approved | L11: M10 | M11: Potential personal data | N11: Encryption; RBAC; masking | O11: Lens cleaning and accuracy checks | P11: Controller uses safe fixed logic | Q11: Medium | R11: Proposed requirement; verify with site design
A12: M09 | B12: ANPR camera | C12: Captures plate evidence | D12: Synthetic plates only | E12: Only if legally authorised | F12: Only if legally authorised | G12: Confirmed enforcement viewpoint | I12: PoE/UPS | J12: Restricted network | K12: Plate and event | L12: Legal authority | M12: High privacy impact | N12: Separate enclave; encryption; audit logs | O12: Calibration and evidential checks | P12: Disable ANPR; retain safety operation | Q12: High | R12: Proposed requirement; verify with site design
A13: M10 | B13: Edge AI unit | C13: Local detection with low latency | D13: Conceptual/local simulation | E13: Conditional | F13: Conditional | G13: Locked cabinet | I13: UPS | J13: Secure field network | K13: Objects/confidence/health | L13: M08/M11 | M13: Minimise raw-video transfer | N13: Secure boot; signed updates | O13: Health checks and model validation | P13: Fail to WAIT/fixed plan | Q13: Medium | R13: Proposed requirement; verify with site design
A14: M11 | B14: Radar presence/speed sensor | C14: Measures approach speed/presence | D14: Simulated sensor state | E14: Recommended | F14: Recommended | G14: Each critical approach | I14: Low voltage | J14: Controller/edge | K14: Speed/presence | L14: M01/M10 | M14: No direct identity | N14: Authenticated interface | O14: Calibration | P14: Conservative timing | Q14: Medium | R14: Proposed requirement; verify with site design
A15: M12 | B15: LiDAR | C15: Resolves complex occlusion | D15: Not found | E15: Not normally required | F15: Only after occlusion study | G15: Overhead/roadside | I15: PoE/UPS | J15: Edge link | K15: Point cloud/objects | L15: M10 | M15: Potential track data | N15: Segmentation; minimisation | O15: Calibration/cleaning | P15: Radar/fixed plan | Q15: High | R15: Proposed requirement; verify with site design
... A26: M23 | B26: Manual control interface | C26: Authorised local recovery | D26: Human review concept | E26: Required | F26: Required | G26: Locked cabinet/control room | I26: UPS | J26: Restricted link | K26: Commands/audit | L26: M01 | M26: Operator identity | N26: MFA/RBAC/audit | O26: Procedure drills | P26: Local physical control | Q26: Medium | R26: Proposed requirement; verify with site design

Sheet Signal Sequence Comparison
A1: Signal Sequence Comparison
A2: Conceptual only. Final timings require measured geometry, walking speeds, intergreen calculations and controller validation.
A3: Sequence ID | B3: Configuration | C3: Phase order | D3: Pedestrian service | E3: Turning control | F3: Slow-user extension | G3: School variant | H3: Failure mode | I3: Evidence state
A4: SEQ-B0 | B4: SC-B0 | C4: Approach > request > amber > all-red/stop proof > WALK > clearance > traffic release | D4: Single marked crossing | E4: Both approaches held STOP | F4: Repository uses protected 12 s concept; field timing not applicable | G4: Longer clearance / supervised group | H4: WAIT/HOLD; STOP; local manual review | I4: Repository-verified simulation
A5: SEQ-T1 | B5: SC-T1 | C5: Vehicle stages > pedestrian request > clearance > all conflicting turns RED > WALK by selected leg(s) > clearance > release | D5: Setback leg-by-leg or compatible non-conflicting pair | E5: No permissive turn across active crossing | F5: Detection may extend clearance within approved maximum | G5: School timetable, group detection, parking control, guard input | H5: All-red/WAIT then fixed/manual plan | I5: Conceptual - data required
A6: SEQ-X1 | B6: SC-X1 | C6: Coordinated vehicle stages > request > all-red > fully protected pedestrian phase > clearance > coordinated release | D6: Fully protected phase preferred for initial pilot screening | E6: All turning movements across active crossings prohibited | F6: Zone occupancy extends clearance; never shortens below design minimum | G6: Group holding and extended clearance; consider one-road-at-a-time if delay/capacity requires | H6: All-red/WAIT then fixed/manual plan | I6: Conceptual - data required
A7: SEQ-X1-SCR | B7: SC-X1 | C7: All-red > all-pedestrian/diagonal phase > clearance > vehicle stages | D7: Diagonal routes only if desire-line and capacity evidence justify | E7: All vehicle movements stopped | F7: Long diagonal clearance required | G7: Not default; high supervision and demand threshold | H7: Disable scramble on degraded detection; conventional protected plan | I7: Alternative only - data required

Sheet Cost Model
A1: Cost Model
A2: No supplier quotations were supplied. Enter quantities and low/high unit rates; unknowns are not zero.
A3: Contingency | B3: 0.2 | D3: Lifecycle years | E3: 10
A5: Cost ID | B5: Configuration | C5: Category | D5: Item | E5: Quantity | F5: Low unit rate RM | G5: High unit rate RM | H5: Low subtotal RM | I5: High subtotal RM | J5: Annual OPEX low RM | K5: Annual OPEX high RM | L5: Quotation / source status
A6: C001 | B6: SC-T1-N | C6: Civil | D6: Kerb ramps, tactile paving, drainage and refuge works | H6: =IF(COUNTA(E6:F6)<2,"",E6*F6) | I6: =IF(COUNTA(E6:G6)<2,"",E6*G6) | L6: DATA REQUIRED FROM MPAJ / SITE SURVEY
A7: C002 | B7: SC-T1-N | C7: Signals | D7: Controller, heads, poles and accessible indications | H7: =IF(COUNTA(E7:F7)<2,"",E7*F7) | I7: =IF(COUNTA(E7:G7)<2,"",E7*G7) | L7: DATA REQUIRED FROM MPAJ / SITE SURVEY
A8: C003 | B8: SC-T1-N | C8: Sensing | D8: Cameras/radar/edge processing only as justified | H8: =IF(COUNTA(E8:F8)<2,"",E8*F8) | I8: =IF(COUNTA(E8:G8)<2,"",E8*G8) | L8: DATA REQUIRED FROM MPAJ / SITE SURVEY
A9: C004 | B9: SC-T1-N | C9: Electrical | D9: Cabinet, UPS, surge and lighting | H9: =IF(COUNTA(E9:F9)<2,"",E9*F9) | I9: =IF(COUNTA(E9:G9)<2,"",E9*G9) | L9: DATA REQUIRED FROM MPAJ / SITE SURVEY
A10: C005 | B10: SC-T1-N | C10: ICT | D10: Secure communications and monitoring integration | H10: =IF(COUNTA(E10:F10)<2,"",E10*F10) | I10: =IF(COUNTA(E10:G10)<2,"",E10*G10) | L10: DATA REQUIRED FROM MPAJ / SITE SURVEY
A11: C006 | B11: SC-T1-N | C11: Design | D11: Survey, detailed design, RSA, testing and approvals | H11: =IF(COUNTA(E11:F11)<2,"",E11*F11) | I11: =IF(COUNTA(E11:G11)<2,"",E11*G11) | L11: DATA REQUIRED FROM MPAJ / SITE SURVEY
A12: C007 | B12: SC-T1-N | C12: Operations | D12: Maintenance, calibration, connectivity and support | H12: =IF(COUNTA(E12:F12)<2,"",E12*F12) | I12: =IF(COUNTA(E12:G12)<2,"",E12*G12) | L12: DATA REQUIRED FROM MPAJ / SITE SURVEY
A13: C008 | B13: SC-T1-S | C13: Civil | D13: Kerb ramps, tactile paving, drainage and refuge works | H13: =IF(COUNTA(E13:F13)<2,"",E13*F13) | I13: =IF(COUNTA(E13:G13)<2,"",E13*G13) | L13: DATA REQUIRED FROM MPAJ / SITE SURVEY
A14: C009 | B14: SC-T1-S | C14: Signals | D14: Controller, heads, poles and accessible indications | H14: =IF(COUNTA(E14:F14)<2,"",E14*F14) | I14: =IF(COUNTA(E14:G14)<2,"",E14*G14) | L14: DATA REQUIRED FROM MPAJ / SITE SURVEY
A15: C010 | B15: SC-T1-S | C15: Sensing | D15: Cameras/radar/edge processing only as justified | H15: =IF(COUNTA(E15:F15)<2,"",E15*F15) | I15: =IF(COUNTA(E15:G15)<2,"",E15*G15) | L15: DATA REQUIRED FROM MPAJ / SITE SURVEY
A16: C011 | B16: SC-T1-S | C16: Electrical | D16: Cabinet, UPS, surge and lighting | H16: =IF(COUNTA(E16:F16)<2,"",E16*F16) | I16: =IF(COUNTA(E16:G16)<2,"",E16*G16) | L16: DATA REQUIRED FROM MPAJ / SITE SURVEY
A17: C012 | B17: SC-T1-S | C17: ICT | D17: Secure communications and monitoring integration | H17: =IF(COUNTA(E17:F17)<2,"",E17*F17) | I17: =IF(COUNTA(E17:G17)<2,"",E17*G17) | L17: DATA REQUIRED FROM MPAJ / SITE SURVEY
